Workbook
Name alpha__LES: 'A.2 & A.3 Time Series Models'!$AR$3
Name alpha__SES: 'A.2 & A.3 Time Series Models'!$AE$3
Name beta__LES: 'A.2 & A.3 Time Series Models'!$AR$4
Name Bin_Size: 'B.1 & B.2 Simulation'!$F$11
Name Bin_Size: #REF!
Name Bin_Start: 'B.1 & B.2 Simulation'!$R$3
Name Bin_Start: #REF!
Name Bin_Stop: 'B.1 & B.2 Simulation'!$S$3
Name Bin_Stop: #REF!
Name Bins: 'B.1 & B.2 Simulation'!$R$6:$R$32
Name Bins: #REF!
Name Bins_Number: 'B.1 & B.2 Simulation'!$F$13
Name Bins_Number: #REF!
Name Expected_LT_Demand: 'B.1 & B.2 Simulation'!$F$5
Name Expected_LT_Demand: #REF!
Name Lead_Time: 'A.4 Safety Stock'!$B$5:$C$5
Name MAD_LES: 'A.2 & A.3 Time Series Models'!$AN$3
Name MAPE_LES: 'A.2 & A.3 Time Series Models'!$AN$4
Name Maximum_Profit: 'B.1 & B.2 Simulation'!$I$16
Name Maximum_Profit: #REF!
Name Minimum_Profit: 'B.1 & B.2 Simulation'!$I$15
Name Minimum_Profit: #REF!
Name MSE_LES: 'A.2 & A.3 Time Series Models'!$AN$5
Name Range_of_Profits: 'B.1 & B.2 Simulation'!$I$17
Name Range_of_Profits: #REF!
Name RMSE_LES: 'A.2 & A.3 Time Series Models'!$AN$6
Name Total_Trials: 'B.1 & B.2 Simulation'!$I$19
Name Total_Trials: #REF!
Name Trials_below_Mean: 'B.1 & B.2 Simulation'!$I$18
Name Trials_below_Mean: #REF!
Name Unit_cost: 'B.1 & B.2 Simulation'!$F$7
Name Unit_cost: #REF!
Name Unit_price: 'B.1 & B.2 Simulation'!$F$6
Name Unit_price: #REF!

Sheet Time Series Plot
A1: Indigo Textiles T-shirt Exports in thousands
A9: Period | B9: Year | C9: Quarter | D9: T-Shirts (000's)
A10: 1 | B10: 2018 | C10: 1 | D10: 365.6
A11: 2 | B11: 2018 | C11: 2 | D11: 412.5
A12: 3 | B12: 2018 | C12: 3 | D12: 349
A13: 4 | B13: 2018 | C13: 4 | D13: 271.1
A14: 5 | B14: 2019 | C14: 1 | D14: 231.5
A15: 6 | B15: 2019 | C15: 2 | D15: 294.4
A16: 7 | B16: 2019 | C16: 3 | D16: 233.1
A17: 8 | B17: 2019 | C17: 4 | D17: 146.4
A18: 9 | B18: 2020 | C18: 1 | D18: 122.2
A19: 10 | B19: 2020 | C19: 2 | D19: 158.6
A20: 11 | B20: 2020 | C20: 3 | D20: 163
A21: 12 | B21: 2020 | C21: 4 | D21: 139.2
... A26: 17 | B26: 2022 | C26: 1 | D26: 128.4
A27: 18 | B27: 2022 | C27: 2 | D27: 171.8 | G27: Observations:
A28: 19 | B28: 2022 | C28: 3 | D28: 168.4
A29: 20 | B29: 2022 | C29: 4 | D29: 155.5 | G29: Early decline (2018–2020): Possibly due to market shifts or global shocks (e.g., COVID).
A30: 21 | B30: 2023 | C30: 1 | D30: 170.8
A31: 22 | B31: 2023 | C31: 2 | D31: 217.7 | G31: Flattened/stable period (2020–2022): Exports plateau around 130–170K.
A32: 23 | B32: 2023 | C32: 3 | D32: 227.8
A33: 24 | B33: 2023 | C33: 4 | D33: 213.4 | G33: Upward recovery (2023–2024): Clear resurgence — great indicator for forecasting.
A34: 25 | B34: 2024 | C34: 1 | D34: 211
A35: 26 | B35: 2024 | C35: 2 | D35: 275.7
A36: 27 | B36: 2024 | C36: 3 | D36: 260.4
A37: 28 | B37: 2024 | C37: 4 | D37: 243.8
A38: 29 | B38: 2025 | C38: 1
A39: 30 | B39: 2025 | C39: 2
A40: 31 | B40: 2025 | C40: 3
A41: 32 | B41: 2025 | C41: 4
A42: 33 | B42: 2026 | C42: 1
A43: 34 | B43: 2026 | C43: 2
A44: 35 | B44: 2026 | C44: 3
A45: 36 | B45: 2026 | C45: 4

Sheet A.1 Time Series Exploration
A1: Reconstruct Time Series from components (review)
A3: Period | B3: Year | C3: T-Shirts (000's) | D3: Moving Avg - 4 | E3: Trend (CMA - 4) | F3: Detrending | G3: Quarter | H3: Seasonal Profile | I3: Trend + Season | J3: Noise | K3: Reconstructed time series
A4: ='Time Series Plot'!A10 -> 1 | B4: ='Time Series Plot'!B10 & " - Q" & 'Time Series Plot'!C10 -> 2018 - Q1 | C4: ='Time Series Plot'!D10 -> 365.6
A5: ='Time Series Plot'!A11 -> 2 | B5: ='Time Series Plot'!B11 & " - Q" & 'Time Series Plot'!C11 -> 2018 - Q2 | C5: ='Time Series Plot'!D11 -> 412.5 | D5: =AVERAGE(C4:C7) -> 349.55
A6: ='Time Series Plot'!A12 -> 3 | B6: ='Time Series Plot'!B12 & " - Q" & 'Time Series Plot'!C12 -> 2018 - Q3 | C6: ='Time Series Plot'!D12 -> 349 | D6: =AVERAGE(C5:C8) -> 316.025 | E6: =AVERAGE(D5:D6) -> 332.7875 | F6: =C6-E6 -> 16.2125 | G6: ="Q" &'Time Series Plot'!C10 -> Q1 | H6: =Z14 -> 13.020833 | I6: =E6+H6 -> 345.80833 | J6: =I6-C6 -> -3.1916667 | K6: =E6+H6+J6 -> 342.61667
A7: ='Time Series Plot'!A13 -> 4 | B7: ='Time Series Plot'!B13 & " - Q" & 'Time Series Plot'!C13 -> 2018 - Q4 | C7: ='Time Series Plot'!D13 -> 271.1 | D7: =AVERAGE(C6:C9) -> 286.5 | E7: =AVERAGE(D6:D7) -> 301.2625 | F7: =C7-E7 -> -30.1625 | G7: ="Q" &'Time Series Plot'!C11 -> Q2 | H7: =Z15 -> -20.491667 | I7: =E7+H7 -> 280.77083 | J7: =I7-C7 -> 9.6708333 | K7: =E7+H7+J7 -> 290.44167
A8: ='Time Series Plot'!A14 -> 5 | B8: ='Time Series Plot'!B14 & " - Q" & 'Time Series Plot'!C14 -> 2019 - Q1 | C8: ='Time Series Plot'!D14 -> 231.5 | D8: =AVERAGE(C7:C10) -> 257.525 | E8: =AVERAGE(D7:D8) -> 272.0125 | F8: =C8-E8 -> -40.5125 | G8: ="Q" &'Time Series Plot'!C12 -> Q3 | H8: =Z12 -> -23.1125 | I8: =E8+H8 -> 248.9 | J8: =I8-C8 -> 17.4 | K8: =E8+H8+J8 -> 266.3
A9: ='Time Series Plot'!A15 -> 6 | B9: ='Time Series Plot'!B15 & " - Q" & 'Time Series Plot'!C15 -> 2019 - Q2 | C9: ='Time Series Plot'!D15 -> 294.4 | D9: =AVERAGE(C8:C11) -> 226.35 | E9: =AVERAGE(D8:D9) -> 241.9375 | F9: =C9-E9 -> 52.4625 | G9: ="Q" &'Time Series Plot'!C13 -> Q4 | H9: =Z13 -> 24.91875 | I9: =E9+H9 -> 266.85625 | J9: =I9-C9 -> -27.54375 | K9: =E9+H9+J9 -> 239.3125
A10: ='Time Series Plot'!A16 -> 7 | B10: ='Time Series Plot'!B16 & " - Q" & 'Time Series Plot'!C16 -> 2019 - Q3 | C10: ='Time Series Plot'!D16 -> 233.1 | D10: =AVERAGE(C9:C12) -> 199.025 | E10: =AVERAGE(D9:D10) -> 212.6875 | F10: =C10-E10 -> 20.4125 | G10: ="Q" &'Time Series Plot'!C14 -> Q1 | H10: 13.020833 | I10: =E10+H10 -> 225.70833 | J10: =I10-C10 -> -7.3916667 | K10: =E10+H10+J10 -> 218.31667 | O10: Table II - Detrended time series by Years | Z10: Seasonal Profile | AD10: Seasonal Profile | AE10: Adj. Seasonal Profile
A11: ='Time Series Plot'!A17 -> 8 | B11: ='Time Series Plot'!B17 & " - Q" & 'Time Series Plot'!C17 -> 2019 - Q4 | C11: ='Time Series Plot'!D17 -> 146.4 | D11: =AVERAGE(C10:C13) -> 165.075 | E11: =AVERAGE(D10:D11) -> 182.05 | F11: =C11-E11 -> -35.65 | G11: ="Q" &'Time Series Plot'!C15 -> Q2 | H11: -20.491667 | I11: =E11+H11 -> 161.55833 | J11: =I11-C11 -> 15.158333 | K11: =E11+H11+J11 -> 176.71667 | O11: Quarter/Year | P11: 2018 | Q11: 2019 | R11: 2020 | S11: 2021 | T11: 2022 | U11: 2023 | V11: 2024 | Y11: Quater\Year | AC11: Quater\Year
A12: ='Time Series Plot'!A18 -> 9 | B12: ='Time Series Plot'!B18 & " - Q" & 'Time Series Plot'!C18 -> 2020 - Q1 | C12: ='Time Series Plot'!D18 -> 122.2 | D12: =AVERAGE(C11:C14) -> 147.55 | E12: =AVERAGE(D11:D12) -> 156.3125 | F12: =C12-E12 -> -34.1125 | G12: ="Q" &'Time Series Plot'!C16 -> Q3 | H12: -23.1125 | I12: =E12+H12 -> 133.2 | J12: =I12-C12 -> 11 | K12: =E12+H12+J12 -> 144.2 | O12: 1 | Q12: =F8 -> -40.5125 | R12: =F12 -> -34.1125 | S12: =F16 -> -4.35 | T12: =F20 -> -19.925 | U12: =F24 -> -14.725 | V12: =F28 -> -25.05 | Y12: 1 | Z12: =AVERAGE(Q12:V12) -> -23.1125 | AC12: 1 | AD12: =Z12 -> -23.1125 | AE12: =AD12-$AD$17 -> -21.696354
A13: ='Time Series Plot'!A19 -> 10 | B13: ='Time Series Plot'!B19 & " - Q" & 'Time Series Plot'!C19 -> 2020 - Q2 | C13: ='Time Series Plot'!D19 -> 158.6 | D13: =AVERAGE(C12:C15) -> 145.75 | E13: =AVERAGE(D12:D13) -> 146.65 | F13: =C13-E13 -> 11.95 | G13: ="Q" &'Time Series Plot'!C17 -> Q4 | H13: 24.91875 | I13: =E13+H13 -> 171.56875 | J13: =I13-C13 -> 12.96875 | K13: =E13+H13+J13 -> 184.5375 | O13: 2 | Q13: =F9 -> 52.4625 | R13: =F13 -> 11.95 | S13: =F17 -> 17.1 | T13: =F21 -> 18.7125 | U13: =F25 -> 17.5125 | V13: =F29 -> 31.775 | Y13: 2 | Z13: =AVERAGE(Q13:V13) -> 24.91875 | AC13: 2 | AD13: =Z13 -> 24.91875 | AE13: =AD13-$AD$17 -> 26.334896
A14: ='Time Series Plot'!A20 -> 11 | B14: ='Time Series Plot'!B20 & " - Q" & 'Time Series Plot'!C20 -> 2020 - Q3 | C14: ='Time Series Plot'!D20 -> 163 | D14: =AVERAGE(C13:C16) -> 152.65 | E14: =AVERAGE(D13:D14) -> 149.2 | F14: =C14-E14 -> 13.8 | G14: ="Q" &'Time Series Plot'!C18 -> Q1 | H14: 13.020833 | I14: =E14+H14 -> 162.22083 | J14: =I14-C14 -> -0.77916667 | K14: =E14+H14+J14 -> 161.44167 | O14: 3 | P14: =F6 -> 16.2125 | Q14: =F10 -> 20.4125 | R14: =F14 -> 13.8 | S14: =F18 -> 5.275 | T14: =F22 -> 7.075 | U14: =F26 -> 15.35 | Y14: 3 | Z14: =AVERAGE(P14:U14) -> 13.020833 | AC14: 3 | AD14: =Z14 -> 13.020833 | AE14: =AD14-$AD$17 -> 14.436979
A15: ='Time Series Plot'!A21 -> 12 | B15: ='Time Series Plot'!B21 & " - Q" & 'Time Series Plot'!C21 -> 2020 - Q4 | C15: ='Time Series Plot'!D21 -> 139.2 | D15: =AVERAGE(C14:C17) -> 155.3 | E15: =AVERAGE(D14:D15) -> 153.975 | F15: =C15-E15 -> -14.775 | G15: ="Q" &'Time Series Plot'!C19 -> Q2 | H15: -20.491667 | I15: =E15+H15 -> 133.48333 | J15: =I15-C15 -> -5.7166667 | K15: =E15+H15+J15 -> 127.76667 | O15: 4 | P15: =F7 -> -30.1625 | Q15: =F11 -> -35.65 | R15: =F15 -> -14.775 | S15: =F19 -> -14.175 | T15: =F23 -> -16.8625 | U15: =F27 -> -11.325 | Y15: 4 | Z15: =AVERAGE(P15:U15) -> -20.491667 | AC15: 4 | AD15: =Z15 -> -20.491667 | AE15: =AD15-$AD$17 -> -19.075521
A16: ='Time Series Plot'!A22 -> 13 | B16: ='Time Series Plot'!B22 & " - Q" & 'Time Series Plot'!C22 -> 2021 - Q1 | C16: ='Time Series Plot'!D22 -> 149.8 | D16: =AVERAGE(C15:C18) -> 153 | E16: =AVERAGE(D15:D16) -> 154.15 | F16: =C16-E16 -> -4.35 | G16: ="Q" &'Time Series Plot'!C20 -> Q3 | H16: -23.1125 | I16: =E16+H16 -> 131.0375 | J16: =I16-C16 -> -18.7625 | K16: =E16+H16+J16 -> 112.275 | AD16: =SUM(AD12:AD15) -> -5.6645833 | AE16: =SUM(AE12:AE15) -> 0
A17: ='Time Series Plot'!A23 -> 14 | B17: ='Time Series Plot'!B23 & " - Q" & 'Time Series Plot'!C23 -> 2021 - Q2 | C17: ='Time Series Plot'!D23 -> 169.2 | D17: =AVERAGE(C16:C19) -> 151.2 | E17: =AVERAGE(D16:D17) -> 152.1 | F17: =C17-E17 -> 17.1 | G17: ="Q" &'Time Series Plot'!C21 -> Q4 | H17: 24.91875 | I17: =E17+H17 -> 177.01875 | J17: =I17-C17 -> 7.81875 | K17: =E17+H17+J17 -> 184.8375 | AD17: =AD16/4 -> -1.4161458
A18: ='Time Series Plot'!A24 -> 15 | B18: ='Time Series Plot'!B24 & " - Q" & 'Time Series Plot'!C24 -> 2021 - Q3 | C18: ='Time Series Plot'!D24 -> 153.8 | D18: =AVERAGE(C17:C20) -> 145.85 | E18: =AVERAGE(D17:D18) -> 148.525 | F18: =C18-E18 -> 5.275 | G18: ="Q" &'Time Series Plot'!C22 -> Q1 | H18: 13.020833 | I18: =E18+H18 -> 161.54583 | J18: =I18-C18 -> 7.7458333 | K18: =E18+H18+J18 -> 169.29167
A19: ='Time Series Plot'!A25 -> 16 | B19: ='Time Series Plot'!B25 & " - Q" & 'Time Series Plot'!C25 -> 2021 - Q4 | C19: ='Time Series Plot'!D25 -> 132 | D19: =AVERAGE(C18:C21) -> 146.5 | E19: =AVERAGE(D18:D19) -> 146.175 | F19: =C19-E19 -> -14.175 | G19: ="Q" &'Time Series Plot'!C23 -> Q2 | H19: -20.491667 | I19: =E19+H19 -> 125.68333 | J19: =I19-C19 -> -6.3166667 | K19: =E19+H19+J19 -> 119.36667
A20: ='Time Series Plot'!A26 -> 17 | B20: ='Time Series Plot'!B26 & " - Q" & 'Time Series Plot'!C26 -> 2022 - Q1 | C20: ='Time Series Plot'!D26 -> 128.4 | D20: =AVERAGE(C19:C22) -> 150.15 | E20: =AVERAGE(D19:D20) -> 148.325 | F20: =C20-E20 -> -19.925 | G20: ="Q" &'Time Series Plot'!C24 -> Q3 | H20: -23.1125 | I20: =E20+H20 -> 125.2125 | J20: =I20-C20 -> -3.1875 | K20: =E20+H20+J20 -> 122.025
A21: ='Time Series Plot'!A27 -> 18 | B21: ='Time Series Plot'!B27 & " - Q" & 'Time Series Plot'!C27 -> 2022 - Q2 | C21: ='Time Series Plot'!D27 -> 171.8 | D21: =AVERAGE(C20:C23) -> 156.025 | E21: =AVERAGE(D20:D21) -> 153.0875 | F21: =C21-E21 -> 18.7125 | G21: ="Q" &'Time Series Plot'!C25 -> Q4 | H21: 24.91875 | I21: =E21+H21 -> 178.00625 | J21: =I21-C21 -> 6.20625 | K21: =E21+H21+J21 -> 184.2125
A22: ='Time Series Plot'!A28 -> 19 | B22: ='Time Series Plot'!B28 & " - Q" & 'Time Series Plot'!C28 -> 2022 - Q3 | C22: ='Time Series Plot'!D28 -> 168.4 | D22: =AVERAGE(C21:C24) -> 166.625 | E22: =AVERAGE(D21:D22) -> 161.325 | F22: =C22-E22 -> 7.075 | G22: ="Q" &'Time Series Plot'!C26 -> Q1 | H22: 13.020833 | I22: =E22+H22 -> 174.34583 | J22: =I22-C22 -> 5.9458333 | K22: =E22+H22+J22 -> 180.29167
A23: ='Time Series Plot'!A29 -> 20 | B23: ='Time Series Plot'!B29 & " - Q" & 'Time Series Plot'!C29 -> 2022 - Q4 | C23: ='Time Series Plot'!D29 -> 155.5 | D23: =AVERAGE(C22:C25) -> 178.1 | E23: =AVERAGE(D22:D23) -> 172.3625 | F23: =C23-E23 -> -16.8625 | G23: ="Q" &'Time Series Plot'!C27 -> Q2 | H23: -20.491667 | I23: =E23+H23 -> 151.87083 | J23: =I23-C23 -> -3.6291667 | K23: =E23+H23+J23 -> 148.24167
A24: ='Time Series Plot'!A30 -> 21 | B24: ='Time Series Plot'!B30 & " - Q" & 'Time Series Plot'!C30 -> 2023 - Q1 | C24: ='Time Series Plot'!D30 -> 170.8 | D24: =AVERAGE(C23:C26) -> 192.95 | E24: =AVERAGE(D23:D24) -> 185.525 | F24: =C24-E24 -> -14.725 | G24: ="Q" &'Time Series Plot'!C28 -> Q3 | H24: -23.1125 | I24: =E24+H24 -> 162.4125 | J24: =I24-C24 -> -8.3875 | K24: =E24+H24+J24 -> 154.025
A25: ='Time Series Plot'!A31 -> 22 | B25: ='Time Series Plot'!B31 & " - Q" & 'Time Series Plot'!C31 -> 2023 - Q2 | C25: ='Time Series Plot'!D31 -> 217.7 | D25: =AVERAGE(C24:C27) -> 207.425 | E25: =AVERAGE(D24:D25) -> 200.1875 | F25: =C25-E25 -> 17.5125 | G25: ="Q" &'Time Series Plot'!C29 -> Q4 | H25: 24.91875 | I25: =E25+H25 -> 225.10625 | J25: =I25-C25 -> 7.40625 | K25: =E25+H25+J25 -> 232.5125
A26: ='Time Series Plot'!A32 -> 23 | B26: ='Time Series Plot'!B32 & " - Q" & 'Time Series Plot'!C32 -> 2023 - Q3 | C26: ='Time Series Plot'!D32 -> 227.8 | D26: =AVERAGE(C25:C28) -> 217.475 | E26: =AVERAGE(D25:D26) -> 212.45 | F26: =C26-E26 -> 15.35 | G26: ="Q" &'Time Series Plot'!C30 -> Q1 | H26: 13.020833 | I26: =E26+H26 -> 225.47083 | J26: =I26-C26 -> -2.3291667 | K26: =E26+H26+J26 -> 223.14167
A27: ='Time Series Plot'!A33 -> 24 | B27: ='Time Series Plot'!B33 & " - Q" & 'Time Series Plot'!C33 -> 2023 - Q4 | C27: ='Time Series Plot'!D33 -> 213.4 | D27: =AVERAGE(C26:C29) -> 231.975 | E27: =AVERAGE(D26:D27) -> 224.725 | F27: =C27-E27 -> -11.325 | G27: ="Q" &'Time Series Plot'!C31 -> Q2 | H27: -20.491667 | I27: =E27+H27 -> 204.23333 | J27: =I27-C27 -> -9.1666667 | K27: =E27+H27+J27 -> 195.06667
A28: ='Time Series Plot'!A34 -> 25 | B28: ='Time Series Plot'!B34 & " - Q" & 'Time Series Plot'!C34 -> 2024 - Q1 | C28: ='Time Series Plot'!D34 -> 211 | D28: =AVERAGE(C27:C30) -> 240.125 | E28: =AVERAGE(D27:D28) -> 236.05 | F28: =C28-E28 -> -25.05 | G28: ="Q" &'Time Series Plot'!C32 -> Q3 | H28: -23.1125 | I28: =E28+H28 -> 212.9375 | J28: =I28-C28 -> 1.9375 | K28: =E28+H28+J28 -> 214.875
A29: ='Time Series Plot'!A35 -> 26 | B29: ='Time Series Plot'!B35 & " - Q" & 'Time Series Plot'!C35 -> 2024 - Q2 | C29: ='Time Series Plot'!D35 -> 275.7 | D29: =AVERAGE(C28:C31) -> 247.725 | E29: =AVERAGE(D28:D29) -> 243.925 | F29: =C29-E29 -> 31.775 | G29: ="Q" &'Time Series Plot'!C33 -> Q4 | H29: 24.91875 | I29: =E29+H29 -> 268.84375 | J29: =I29-C29 -> -6.85625 | K29: =E29+H29+J29 -> 261.9875
A30: ='Time Series Plot'!A36 -> 27 | B30: ='Time Series Plot'!B36 & " - Q" & 'Time Series Plot'!C36 -> 2024 - Q3 | C30: ='Time Series Plot'!D36 -> 260.4 | G30: ="Q" &'Time Series Plot'!C34 -> Q1
A31: ='Time Series Plot'!A37 -> 28 | B31: ='Time Series Plot'!B37 & " - Q" & 'Time Series Plot'!C37 -> 2024 - Q4 | C31: ='Time Series Plot'!D37 -> 243.8 | G31: ="Q" &'Time Series Plot'!C35 -> Q2
A32: ='Time Series Plot'!A38 -> 29 | B32: ='Time Series Plot'!B38 & " - Q" & 'Time Series Plot'!C38 -> 2025 - Q1 | G32: ="Q" &'Time Series Plot'!C36 -> Q3
A33: ='Time Series Plot'!A39 -> 30 | B33: ='Time Series Plot'!B39 & " - Q" & 'Time Series Plot'!C39 -> 2025 - Q2 | G33: ="Q" &'Time Series Plot'!C37 -> Q4
A34: ='Time Series Plot'!A40 -> 31 | B34: ='Time Series Plot'!B40 & " - Q" & 'Time Series Plot'!C40 -> 2025 - Q3 | G34: ="Q" &'Time Series Plot'!C38 -> Q1
A35: ='Time Series Plot'!A41 -> 32 | B35: ='Time Series Plot'!B41 & " - Q" & 'Time Series Plot'!C41 -> 2025 - Q4 | G35: ="Q" &'Time Series Plot'!C39 -> Q2
A36: ='Time Series Plot'!A42 -> 33 | B36: ='Time Series Plot'!B42 & " - Q" & 'Time Series Plot'!C42 -> 2026 - Q1 | G36: ="Q" &'Time Series Plot'!C40 -> Q3
A37: ='Time Series Plot'!A43 -> 34 | B37: ='Time Series Plot'!B43 & " - Q" & 'Time Series Plot'!C43 -> 2026 - Q2 | G37: ="Q" &'Time Series Plot'!C41 -> Q4
A38: ='Time Series Plot'!A44 -> 35 | B38: ='Time Series Plot'!B44 & " - Q" & 'Time Series Plot'!C44 -> 2026 - Q3 | G38: ="Q" &'Time Series Plot'!C42 -> Q1
A39: ='Time Series Plot'!A45 -> 36 | B39: ='Time Series Plot'!B45 & " - Q" & 'Time Series Plot'!C45 -> 2026 - Q4 | G39: ="Q" &'Time Series Plot'!C43 -> Q2

Sheet A.2 & A.3 Time Series Models
P1: Simple Moving Average Forecast of Level | AA1: Simple Exponential Smoothing (SES) Forecast | AM1: Linear Exponential Smoothing - Forecast | AV1: Comparison of Error
AW2: MAV | AX2: SES | AY2: LES
Q3: MAD | R3: =Q25 -> 71.55 | AA3: MAD | AB3: =AB25 -> 63.89623 | AD3: alpha (a) | AE3: 0.6 | AM3: MAD_LES | AN3: =AN25 -> 37.031267 | AQ3: alpha (a) | AR3: 0.5 | AV3: MAD | AW3: =R3 -> 71.55 | AX3: =AB3 -> 63.89623 | AY3: =MAD_LES -> 37.031267
Q4: MAPE | R4: =R25 -> 0.301153 | AA4: MAPE | AB4: =AC25 -> 0.26687122 | AM4: MAPE_LES | AN4: =AO25 -> 0.15326717 | AQ4: beta (b) | AR4: 0.8 | AV4: MAPE | AW4: =R4 -> 0.301153 | AX4: =AB4 -> 0.26687122 | AY4: =MAPE_LES -> 0.15326717
Q5: MSE | R5: =S25 -> 6051.0744 | AA5: MSE | AB5: =AE25 -> 5014.4001 | AM5: MSE_LES | AN5: =AQ25 -> 1847.6965 | AP5: =AP6*52 -> 41.6 | AQ5: =AQ6*52 -> 10.4 | AV5: RMSE | AW5: =R6 -> 77.788652 | AX5: =AB6 -> 70.812429 | AY5: =RMSE_LES -> 42.98484
Q6: RMSE | R6: =T25 -> 77.788652 | AA6: RMSE | AB6: =AD25 -> 70.812429 | AM6: RMSE_LES | AN6: =AP25 -> 42.98484 | AP6: 0.8 | AQ6: 0.2
D7: Training Data | E7: Test Data
A8: Period | B8: Year | C8: T-Shirts (000's) | D8: In-Sample | E8: Out-of-Sample | F8: MAV Training | G8: MAV Forecast | I8: SES Training | J8: SES Forecast | L8: Level | M8: Trend (LES) | N8: LES Forecast
A9: ='A.1 Time Series Exploration'!A4 -> 1 | B9: ='A.1 Time Series Exploration'!B4 -> 2018 - Q1 | C9: ='A.1 Time Series Exploration'!C4 -> 365.6 | D9: =C9 -> 365.6 | I9: =D9 -> 365.6 | L9: =C9 -> 365.6 | M9: 0
A10: ='A.1 Time Series Exploration'!A5 -> 2 | B10: ='A.1 Time Series Exploration'!B5 -> 2018 - Q2 | C10: ='A.1 Time Series Exploration'!C5 -> 412.5 | D10: =C10 -> 412.5 | I10: =alpha__SES*D9+(1-alpha__SES)*I9 -> 365.6 | L10: =alpha__LES*D10+(1-alpha__LES)*(L9+M9) -> 389.05 | M10: =beta__LES*(L10-L9)+(1-beta__LES)*M9 -> 18.76
A11: ='A.1 Time Series Exploration'!A6 -> 3 | B11: ='A.1 Time Series Exploration'!B6 -> 2018 - Q3 | C11: ='A.1 Time Series Exploration'!C6 -> 349 | D11: =C11 -> 349 | I11: =alpha__SES*D10+(1-alpha__SES)*I10 -> 393.74 | L11: =alpha__LES*D11+(1-alpha__LES)*(L10+M10) -> 378.405 | M11: =beta__LES*(L11-L10)+(1-beta__LES)*M10 -> -4.764
A12: ='A.1 Time Series Exploration'!A7 -> 4 | B12: ='A.1 Time Series Exploration'!B7 -> 2018 - Q4 | C12: ='A.1 Time Series Exploration'!C7 -> 271.1 | D12: =C12 -> 271.1 | I12: =alpha__SES*D11+(1-alpha__SES)*I11 -> 366.896 | L12: =alpha__LES*D12+(1-alpha__LES)*(L11+M11) -> 322.3705 | M12: =beta__LES*(L12-L11)+(1-beta__LES)*M11 -> -45.7804
A13: ='A.1 Time Series Exploration'!A8 -> 5 | B13: ='A.1 Time Series Exploration'!B8 -> 2019 - Q1 | C13: ='A.1 Time Series Exploration'!C8 -> 231.5 | D13: =C13 -> 231.5 | F13: =AVERAGE(D9:D12) -> 349.55 | I13: =alpha__SES*D12+(1-alpha__SES)*I12 -> 309.4184 | L13: =alpha__LES*D13+(1-alpha__LES)*(L12+M12) -> 254.04505 | M13: =beta__LES*(L13-L12)+(1-beta__LES)*M12 -> -63.81644
A14: ='A.1 Time Series Exploration'!A9 -> 6 | B14: ='A.1 Time Series Exploration'!B9 -> 2019 - Q2 | C14: ='A.1 Time Series Exploration'!C9 -> 294.4 | D14: =C14 -> 294.4 | F14: =AVERAGE(D10:D13) -> 316.025 | I14: =alpha__SES*D13+(1-alpha__SES)*I13 -> 262.66736 | L14: =alpha__LES*D14+(1-alpha__LES)*(L13+M13) -> 242.3143 | M14: =beta__LES*(L14-L13)+(1-beta__LES)*M13 -> -22.147884
A15: ='A.1 Time Series Exploration'!A10 -> 7 | B15: ='A.1 Time Series Exploration'!B10 -> 2019 - Q3 | C15: ='A.1 Time Series Exploration'!C10 -> 233.1 | D15: =C15 -> 233.1 | F15: =AVERAGE(D11:D14) -> 286.5 | I15: =alpha__SES*D14+(1-alpha__SES)*I14 -> 281.70694 | L15: =alpha__LES*D15+(1-alpha__LES)*(L14+M14) -> 226.63321 | M15: =beta__LES*(L15-L14)+(1-beta__LES)*M14 -> -16.974452
A16: ='A.1 Time Series Exploration'!A11 -> 8 | B16: ='A.1 Time Series Exploration'!B11 -> 2019 - Q4 | C16: ='A.1 Time Series Exploration'!C11 -> 146.4 | D16: =C16 -> 146.4 | F16: =AVERAGE(D12:D15) -> 257.525 | I16: =alpha__SES*D15+(1-alpha__SES)*I15 -> 252.54278 | L16: =alpha__LES*D16+(1-alpha__LES)*(L15+M15) -> 178.02938 | M16: =beta__LES*(L16-L15)+(1-beta__LES)*M15 -> -42.277956
A17: ='A.1 Time Series Exploration'!A12 -> 9 | B17: ='A.1 Time Series Exploration'!B12 -> 2020 - Q1 | C17: ='A.1 Time Series Exploration'!C12 -> 122.2 | D17: =C17 -> 122.2 | F17: =AVERAGE(D13:D16) -> 226.35 | I17: =alpha__SES*D16+(1-alpha__SES)*I16 -> 188.85711 | L17: =alpha__LES*D17+(1-alpha__LES)*(L16+M16) -> 128.97571 | M17: =beta__LES*(L17-L16)+(1-beta__LES)*M16 -> -47.698525
A18: ='A.1 Time Series Exploration'!A13 -> 10 | B18: ='A.1 Time Series Exploration'!B13 -> 2020 - Q2 | C18: ='A.1 Time Series Exploration'!C13 -> 158.6 | D18: =C18 -> 158.6 | F18: =AVERAGE(D14:D17) -> 199.025 | I18: =alpha__SES*D17+(1-alpha__SES)*I17 -> 148.86284 | L18: =alpha__LES*D18+(1-alpha__LES)*(L17+M17) -> 119.93859 | M18: =beta__LES*(L18-L17)+(1-beta__LES)*M17 -> -16.7694
A19: ='A.1 Time Series Exploration'!A14 -> 11 | B19: ='A.1 Time Series Exploration'!B14 -> 2020 - Q3 | C19: ='A.1 Time Series Exploration'!C14 -> 163 | D19: =C19 -> 163 | F19: =AVERAGE(D15:D18) -> 165.075 | I19: =alpha__SES*D18+(1-alpha__SES)*I18 -> 154.70514 | L19: =alpha__LES*D19+(1-alpha__LES)*(L18+M18) -> 133.0846 | M19: =beta__LES*(L19-L18)+(1-beta__LES)*M18 -> 7.1629228
A20: ='A.1 Time Series Exploration'!A15 -> 12 | B20: ='A.1 Time Series Exploration'!B15 -> 2020 - Q4 | C20: ='A.1 Time Series Exploration'!C15 -> 139.2 | D20: =C20 -> 139.2 | F20: =AVERAGE(D16:D19) -> 147.55 | I20: =alpha__SES*D19+(1-alpha__SES)*I19 -> 159.68206 | L20: =alpha__LES*D20+(1-alpha__LES)*(L19+M19) -> 139.72376 | M20: =beta__LES*(L20-L19)+(1-beta__LES)*M19 -> 6.743915
A21: ='A.1 Time Series Exploration'!A16 -> 13 | B21: ='A.1 Time Series Exploration'!B16 -> 2021 - Q1 | C21: ='A.1 Time Series Exploration'!C16 -> 149.8 | D21: =C21 -> 149.8 | F21: =AVERAGE(D17:D20) -> 145.75 | I21: =alpha__SES*D20+(1-alpha__SES)*I20 -> 147.39282 | L21: =alpha__LES*D21+(1-alpha__LES)*(L20+M20) -> 148.13384 | M21: =beta__LES*(L21-L20)+(1-beta__LES)*M20 -> 8.076845
A22: ='A.1 Time Series Exploration'!A17 -> 14 | B22: ='A.1 Time Series Exploration'!B17 -> 2021 - Q2 | C22: ='A.1 Time Series Exploration'!C17 -> 169.2 | D22: =C22 -> 169.2 | F22: =AVERAGE(D18:D21) -> 152.65 | I22: =alpha__SES*D21+(1-alpha__SES)*I21 -> 148.83713 | L22: =alpha__LES*D22+(1-alpha__LES)*(L21+M21) -> 162.70534 | M22: =beta__LES*(L22-L21)+(1-beta__LES)*M21 -> 13.272572
A23: ='A.1 Time Series Exploration'!A18 -> 15 | B23: ='A.1 Time Series Exploration'!B18 -> 2021 - Q3 | C23: ='A.1 Time Series Exploration'!C18 -> 153.8 | D23: =C23 -> 153.8 | F23: =AVERAGE(D19:D22) -> 155.3 | I23: =alpha__SES*D22+(1-alpha__SES)*I22 -> 161.05485 | L23: =alpha__LES*D23+(1-alpha__LES)*(L22+M22) -> 164.88896 | M23: =beta__LES*(L23-L22)+(1-beta__LES)*M22 -> 4.4014067 | P23: Bias | S23: Root of Mean Square Error | AA23: Bias | AD23: Root of Mean Square Error | AM23: Bias | AP23: Root of Mean Square Error
A24: ='A.1 Time Series Exploration'!A19 -> 16 | B24: ='A.1 Time Series Exploration'!B19 -> 2021 - Q4 | C24: ='A.1 Time Series Exploration'!C19 -> 132 | D24: =C24 -> 132 | F24: =AVERAGE(D20:D23) -> 153 | I24: =alpha__SES*D23+(1-alpha__SES)*I23 -> 156.70194 | L24: =alpha__LES*D24+(1-alpha__LES)*(L23+M23) -> 150.64518 | M24: =beta__LES*(L24-L23)+(1-beta__LES)*M23 -> -10.514739 | P24: ME_MAV | Q24: MAD_MAV | R24: MAPE_MAV | S24: MSE_MAV | T24: RMSE_MAV | AA24: ME_SES | AB24: MAD_SES | AC24: MAPE_MAV | AD24: RMSE_SES | AE24: MSE_SES | AM24: ME_LES | AN24: MAD_LES | AO24: MAPE_les | AP24: RMSE_LES | AQ24: MSE_LES
A25: ='A.1 Time Series Exploration'!A20 -> 17 | B25: ='A.1 Time Series Exploration'!B20 -> 2022 - Q1 | C25: ='A.1 Time Series Exploration'!C20 -> 128.4 | D25: =C25 -> 128.4 | F25: =AVERAGE(D21:D24) -> 151.2 | I25: =alpha__SES*D24+(1-alpha__SES)*I24 -> 141.88078 | L25: =alpha__LES*D25+(1-alpha__LES)*(L24+M24) -> 134.26522 | M25: =beta__LES*(L25-L24)+(1-beta__LES)*M24 -> -15.206916 | P25: =AVERAGE(P29:P36) -> -71.55 | Q25: =AVERAGE(Q29:Q36) -> 71.55 | R25: =AVERAGE(R29:R36) -> 0.301153 | S25: =AVERAGE(S29:S36) -> 6051.0744 | T25: =SQRT(S25) -> 77.788652 | AA25: =AVERAGE(AA29:AA36) -> -63.89623 | AB25: =AVERAGE(AB29:AB36) -> 63.89623 | AC25: =AVERAGE(AC29:AC36) -> 0.26687122 | AD25: =SQRT(AE25) -> 70.812429 | AE25: =AVERAGE(AD29:AD36) -> 5014.4001 | AM25: =AVERAGE(AM29:AM36) -> -37.031267 | AN25: =AVERAGE(AN29:AN36) -> 37.031267 | AO25: =AVERAGE(AO29:AO36) -> 0.15326717 | AP25: =SQRT(AQ25) -> 42.98484 | AQ25: =AVERAGE(AP29:AP36) -> 1847.6965
A26: ='A.1 Time Series Exploration'!A21 -> 18 | B26: ='A.1 Time Series Exploration'!B21 -> 2022 - Q2 | C26: ='A.1 Time Series Exploration'!C21 -> 171.8 | D26: =C26 -> 171.8 | F26: =AVERAGE(D22:D25) -> 145.85 | I26: =alpha__SES*D25+(1-alpha__SES)*I25 -> 133.79231 | L26: =alpha__LES*D26+(1-alpha__LES)*(L25+M25) -> 145.42915 | M26: =beta__LES*(L26-L25)+(1-beta__LES)*M25 -> 5.8897619 | P26: (Forecast - Actual) | AA26: (Forecast - Actual) | AM26: (Forecast - Actual)
A27: ='A.1 Time Series Exploration'!A22 -> 19 | B27: ='A.1 Time Series Exploration'!B22 -> 2022 - Q3 | C27: ='A.1 Time Series Exploration'!C22 -> 168.4 | D27: =C27 -> 168.4 | F27: =AVERAGE(D23:D26) -> 146.5 | I27: =alpha__SES*D26+(1-alpha__SES)*I26 -> 156.59692 | L27: =alpha__LES*D27+(1-alpha__LES)*(L26+M26) -> 159.85946 | M27: =beta__LES*(L27-L26)+(1-beta__LES)*M26 -> 12.722196 | P27: e | Q27: |e| | R27: |e|/actual | S27: e^2 | AA27: e | AB27: |e| | AC27: |e|/actual | AD27: e^2 | AM27: e | AN27: |e| | AO27: |e|/actual | AP27: e^2
A28: ='A.1 Time Series Exploration'!A23 -> 20 | B28: ='A.1 Time Series Exploration'!B23 -> 2022 - Q4 | C28: ='A.1 Time Series Exploration'!C23 -> 155.5 | D28: =C28 -> 155.5 | E28: =C28 -> 155.5 | F28: =AVERAGE(D24:D27) -> 150.15 | I28: =alpha__SES*D27+(1-alpha__SES)*I27 -> 163.67877 | J28: =I28 -> 163.67877 | L28: =alpha__LES*D28+(1-alpha__LES)*(L27+M27) -> 164.04083 | M28: =beta__LES*(L28-L27)+(1-beta__LES)*M27 -> 5.8895346 | N28: =L28 -> 164.04083 | P28: Error | Q28: Absolute Deviation | R28: Absolute Percentage Error | S28: Squared Error | AA28: Error | AB28: Absolute Deviation | AC28: Absolute Percentage Error | AD28: Squared Error | AM28: Error | AN28: Absolute Deviation | AO28: Absolute Percentage Error | AP28: Squared Error
A29: ='A.1 Time Series Exploration'!A24 -> 21 | B29: ='A.1 Time Series Exploration'!B24 -> 2023 - Q1 | C29: ='A.1 Time Series Exploration'!C24 -> 170.8 | E29: =C29 -> 170.8 | F29: =AVERAGE(D25:D28) -> 156.025 | G29: =F29 -> 156.025 | J29: =J28 -> 163.67877 | M29: =M28 -> 5.8895346 | N29: =M28+N28 -> 169.93036 | P29: =G29-E29 -> -14.775 | Q29: =ABS(P29) -> 14.775 | R29: =Q29/E29 -> 0.086504684 | S29: =P29^2 -> 218.30063 | AA29: =J29-E29 -> -7.1212303 | AB29: =ABS(AA29) -> 7.1212303 | AC29: =AB29/E29 -> 0.041693386 | AD29: =AA29^2 -> 50.711921 | AM29: =N29-E29 -> -0.86963868 | AN29: =ABS(AM29) -> 0.86963868 | AO29: =AN29/C29 -> 0.0050915614 | AP29: =AM29^2 -> 0.75627143
A30: ='A.1 Time Series Exploration'!A25 -> 22 | B30: ='A.1 Time Series Exploration'!B25 -> 2023 - Q2 | C30: ='A.1 Time Series Exploration'!C25 -> 217.7 | E30: =C30 -> 217.7 | G30: =G29 -> 156.025 | J30: =J29 -> 163.67877 | M30: =M29 -> 5.8895346 | N30: =M29+N29 -> 175.8199 | P30: =G30-E30 -> -61.675 | Q30: =ABS(P30) -> 61.675 | R30: =Q30/E30 -> 0.28330271 | S30: =P30^2 -> 3803.8056 | AA30: =J30-E30 -> -54.02123 | AB30: =ABS(AA30) -> 54.02123 | AC30: =AB30/E30 -> 0.24814529 | AD30: =AA30^2 -> 2918.2933 | AM30: =N30-E30 -> -41.880104 | AN30: =ABS(AM30) -> 41.880104 | AO30: =AN30/C30 -> 0.19237531 | AP30: =AM30^2 -> 1753.9431
A31: ='A.1 Time Series Exploration'!A26 -> 23 | B31: ='A.1 Time Series Exploration'!B26 -> 2023 - Q3 | C31: ='A.1 Time Series Exploration'!C26 -> 227.8 | E31: =C31 -> 227.8 | G31: =G30 -> 156.025 | J31: =J30 -> 163.67877 | M31: =M30 -> 5.8895346 | N31: =M30+N30 -> 181.70943 | P31: =G31-E31 -> -71.775 | Q31: =ABS(P31) -> 71.775 | R31: =Q31/E31 -> 0.31507902 | S31: =P31^2 -> 5151.6506 | AA31: =J31-E31 -> -64.12123 | AB31: =ABS(AA31) -> 64.12123 | AC31: =AB31/E31 -> 0.28148038 | AD31: =AA31^2 -> 4111.5322 | AM31: =N31-E31 -> -46.090569 | AN31: =ABS(AM31) -> 46.090569 | AO31: =AN31/C31 -> 0.2023291 | AP31: =AM31^2 -> 2124.3406
A32: ='A.1 Time Series Exploration'!A27 -> 24 | B32: ='A.1 Time Series Exploration'!B27 -> 2023 - Q4 | C32: ='A.1 Time Series Exploration'!C27 -> 213.4 | E32: =C32 -> 213.4 | G32: =G31 -> 156.025 | J32: =J31 -> 163.67877 | M32: =M31 -> 5.8895346 | N32: =M31+N31 -> 187.59897 | P32: =G32-E32 -> -57.375 | Q32: =ABS(P32) -> 57.375 | R32: =Q32/E32 -> 0.26886129 | S32: =P32^2 -> 3291.8906 | AA32: =J32-E32 -> -49.72123 | AB32: =ABS(AA32) -> 49.72123 | AC32: =AB32/E32 -> 0.23299546 | AD32: =AA32^2 -> 2472.2007 | AM32: =N32-E32 -> -25.801035 | AN32: =ABS(AM32) -> 25.801035 | AO32: =AN32/C32 -> 0.12090457 | AP32: =AM32^2 -> 665.69339
A33: ='A.1 Time Series Exploration'!A28 -> 25 | B33: ='A.1 Time Series Exploration'!B28 -> 2024 - Q1 | C33: ='A.1 Time Series Exploration'!C28 -> 211 | E33: =C33 -> 211 | G33: =G32 -> 156.025 | J33: =J32 -> 163.67877 | M33: =M32 -> 5.8895346 | N33: =M32+N32 -> 193.4885 | P33: =G33-E33 -> -54.975 | Q33: =ABS(P33) -> 54.975 | R33: =Q33/E33 -> 0.26054502 | S33: =P33^2 -> 3022.2506 | AA33: =J33-E33 -> -47.32123 | AB33: =ABS(AA33) -> 47.32123 | AC33: =AB33/E33 -> 0.22427123 | AD33: =AA33^2 -> 2239.2988 | AM33: =N33-E33 -> -17.5115 | AN33: =ABS(AM33) -> 17.5115 | AO33: =AN33/C33 -> 0.082992891 | AP33: =AM33^2 -> 306.65264
A34: ='A.1 Time Series Exploration'!A29 -> 26 | B34: ='A.1 Time Series Exploration'!B29 -> 2024 - Q2 | C34: ='A.1 Time Series Exploration'!C29 -> 275.7 | E34: =C34 -> 275.7 | G34: =G33 -> 156.025 | J34: =J33 -> 163.67877 | M34: =M33 -> 5.8895346 | N34: =M33+N33 -> 199.37803 | P34: =G34-E34 -> -119.675 | Q34: =ABS(P34) -> 119.675 | R34: =Q34/E34 -> 0.4340769 | S34: =P34^2 -> 14322.106 | AA34: =J34-E34 -> -112.02123 | AB34: =ABS(AA34) -> 112.02123 | AC34: =AB34/E34 -> 0.40631567 | AD34: =AA34^2 -> 12548.756 | AM34: =N34-E34 -> -76.321965 | AN34: =ABS(AM34) -> 76.321965 | AO34: =AN34/C34 -> 0.27682976 | AP34: =AM34^2 -> 5825.0424
A35: ='A.1 Time Series Exploration'!A30 -> 27 | B35: ='A.1 Time Series Exploration'!B30 -> 2024 - Q3 | C35: ='A.1 Time Series Exploration'!C30 -> 260.4 | E35: =C35 -> 260.4 | G35: =G34 -> 156.025 | J35: =J34 -> 163.67877 | M35: =M34 -> 5.8895346 | N35: =M34+N34 -> 205.26757 | P35: =G35-E35 -> -104.375 | Q35: =ABS(P35) -> 104.375 | R35: =Q35/E35 -> 0.40082565 | S35: =P35^2 -> 10894.141 | AA35: =J35-E35 -> -96.72123 | AB35: =ABS(AA35) -> 96.72123 | AC35: =AB35/E35 -> 0.3714333 | AD35: =AA35^2 -> 9354.9964 | AM35: =N35-E35 -> -55.132431 | AN35: =ABS(AM35) -> 55.132431 | AO35: =AN35/C35 -> 0.21172208 | AP35: =AM35^2 -> 3039.5849
A36: ='A.1 Time Series Exploration'!A31 -> 28 | B36: ='A.1 Time Series Exploration'!B31 -> 2024 - Q4 | C36: ='A.1 Time Series Exploration'!C31 -> 243.8 | E36: =C36 -> 243.8 | G36: =G35 -> 156.025 | J36: =J35 -> 163.67877 | M36: =M35 -> 5.8895346 | N36: =M35+N35 -> 211.1571 | P36: =G36-E36 -> -87.775 | Q36: =ABS(P36) -> 87.775 | R36: =Q36/E36 -> 0.36002871 | S36: =P36^2 -> 7704.4506 | AA36: =J36-E36 -> -80.12123 | AB36: =ABS(AA36) -> 80.12123 | AC36: =AB36/E36 -> 0.32863507 | AD36: =AA36^2 -> 6419.4115 | AM36: =N36-E36 -> -32.642896 | AN36: =ABS(AM36) -> 32.642896 | AO36: =AN36/C36 -> 0.13389211 | AP36: =AM36^2 -> 1065.5587
A37: ='A.1 Time Series Exploration'!A32 -> 29 | B37: ='A.1 Time Series Exploration'!B32 -> 2025 - Q1 | G37: =G36 -> 156.025 | J37: =J36 -> 163.67877 | M37: =M36 -> 5.8895346 | N37: =M36+N36 -> 217.04664
A38: ='A.1 Time Series Exploration'!A33 -> 30 | B38: ='A.1 Time Series Exploration'!B33 -> 2025 - Q2 | G38: =G37 -> 156.025 | J38: =J37 -> 163.67877 | M38: =M37 -> 5.8895346 | N38: =M37+N37 -> 222.93617
A39: ='A.1 Time Series Exploration'!A34 -> 31 | B39: ='A.1 Time Series Exploration'!B34 -> 2025 - Q3 | G39: =G38 -> 156.025 | J39: =J38 -> 163.67877 | M39: =M38 -> 5.8895346 | N39: =M38+N38 -> 228.82571
A40: ='A.1 Time Series Exploration'!A35 -> 32 | B40: ='A.1 Time Series Exploration'!B35 -> 2025 - Q4 | G40: =G39 -> 156.025 | J40: =J39 -> 163.67877 | M40: =M39 -> 5.8895346 | N40: =M39+N39 -> 234.71524
...

Sheet A.4 Safety Stock
A1: Safety Stock and Re-order Point Calculations
A3: Tasks: After Forecast and RMSE calculations
A4: 1 | B4: Consider what is your lead time for any order (i.e. the time from order till receiving the ordered stock).
B5: Lead Time | C5: 8 | D5: Quarter | E5: (for calculations, should be in same units as each row in time-series)
B6: Right now we will assume this, but you will know this in your forecasting scenario
A8: 2 | B8: Expected Lead Time Demand
B12: Time Periods after Order | C12: Quarter | D12: Forecast
B13: 1 | C13: ='A.2 & A.3 Time Series Models'!B37 -> 2025 - Q1 | D13: ='A.2 & A.3 Time Series Models'!N37 -> 217.04664 | G13: Expected Demand over Lead Time Period
B14: 2 | C14: ='A.2 & A.3 Time Series Models'!B38 -> 2025 - Q2 | D14: ='A.2 & A.3 Time Series Models'!N38 -> 222.93617 | G14: =SUM(D13:D20) -> 1901.2801 | H14: T-Shirts(000's)
B15: 3 | C15: ='A.2 & A.3 Time Series Models'!B39 -> 2025 - Q3 | D15: ='A.2 & A.3 Time Series Models'!N39 -> 228.82571
B16: 4 | C16: ='A.2 & A.3 Time Series Models'!B40 -> 2025 - Q4 | D16: ='A.2 & A.3 Time Series Models'!N40 -> 234.71524
B17: 5 | C17: ='A.2 & A.3 Time Series Models'!B41 -> 2026 - Q1 | D17: ='A.2 & A.3 Time Series Models'!N41 -> 240.60478
B18: 6 | C18: ='A.2 & A.3 Time Series Models'!B42 -> 2026 - Q2 | D18: ='A.2 & A.3 Time Series Models'!N42 -> 246.49431
B19: 7 | C19: ='A.2 & A.3 Time Series Models'!B43 -> 2026 - Q3 | D19: ='A.2 & A.3 Time Series Models'!N43 -> 252.38385
B20: 8 | C20: ='A.2 & A.3 Time Series Models'!B44 -> 2026 - Q4 | D20: ='A.2 & A.3 Time Series Models'!N44 -> 258.27338
N21: Expected LT Demand | P21: Safety Stock | Q21: ROP
M22: T-Shirts(000's) | N22: =G14 -> 1901.2801 | P22: =C38 -> 199.98046 | Q22: =N22+P22 -> 2101.2605 | R22: T-Shirts(000's)
A24: 3 | B24: What Stock-out Risk or Service Level do we want?
B25: Stockout Risk | C25: 0.05
B26: Service Level | C26: =1-C25 -> 0.95 | D26: '=(1- Stockout Risk)
A28: 4 | B28: How many standard deviations gives us this service level?
B29: That is the Z-Score | C29: =_xlfn.NORM.S.INV(C26) -> 1.6448536 | D29: =NORM.S.INV([Service Level Probability])
A31: 5 | B31: Safety stock?
B32: Std. Deviation or RMSE | C32: =RMSE_LES -> 42.98484
C33: x
B34: Square Root of Lead Time | C34: =SQRT(Lead_Time) -> 2.8284271
C35: x
B36: Chosen Z-Score for Risk | C36: =C29 -> 1.6448536
C37: =
B38: Safety Stock for Lead Time | C38: =C32*C34*C36 -> 199.98046 | D38: T-Shirts(000's)
A40: 6 | B40: Re-order Point (ROP)
B41: Expected Demand | C41: =N22 -> 1901.2801
C42: +
B43: Safety Stock | C43: =C38 -> 199.98046
B45: ROP | C45: =C41+C43 -> 2101.2605 | D45: T-Shirts(000's)

Sheet B.1 & B.2 Simulation
A1: Simulation Tutorial - Monte Carlo Simulation Model for Expected Profit
R2: Bin Start | S2: Bin Stop
D3: Inputs | H3: Outcomes | R3: =FLOOR(Minimum_Profit,POWER(10,LEN(TRUNC(Minimum_Profit))-1)) -> 1000000 | S3: =_xlfn.CEILING.MATH(Maximum_Profit,POWER(10,LEN(TRUNC(Maximum_Profit))-1)) -> 7000000
R4: Risk Profile Chart Data
E5: Expected LT Demand | F5: ='A.4 Safety Stock'!N22 -> 1901.2801 | G5: T-Shirts(000's) | H5: Expected demand for us and profit | R5: Bins | S5: Frequency | T5: Cummulative %
E6: Unit price | F6: 8 | R6: =Bin_Start -> 1000000 | S6: {=FREQUENCY(Table14[Profit],Bins)} -> 0 | T6: =IF(ISBLANK(S6),"",SUM($S$6:S6)/Total_Trials) -> 0
E7: Unit cost | F7: 4 | H7: Mean demand fulfilled by us | R7: =IF(R6+Bin_Size>Bin_Stop,"",R6+Bin_Size) -> 1650000 | S7: 9 | T7: =IF(ISBLANK(S7),"",SUM($S$6:S7)/Total_Trials) -> 0.036
E8: Std of LT Demand | F8: ='A.4 Safety Stock'!C32 * 'A.4 Safety Stock'!C34 -> 121.57949 | H8: =AVERAGE(Table14[Share of Lead Time Demand (Units)]) -> 1000166.5 | J8: units | R8: =IF(R7+Bin_Size>Bin_Stop,"",R7+Bin_Size) -> 2300000 | S8: 18 | T8: =IF(ISBLANK(S8),"",SUM($S$6:S8)/Total_Trials) -> 0.108
R9: =IF(R8+Bin_Size>Bin_Stop,"",R8+Bin_Size) -> 2950000 | S9: 25 | T9: =IF(ISBLANK(S9),"",SUM($S$6:S9)/Total_Trials) -> 0.208
E10: Risk Profile Inputs | H10: Mean profit | R10: =IF(R9+Bin_Size>Bin_Stop,"",R9+Bin_Size) -> 3600000 | S10: 35 | T10: =IF(ISBLANK(S10),"",SUM($S$6:S10)/Total_Trials) -> 0.348
E11: Bin Size | F11: 650000 | H11: =AVERAGE(Table14[Profit]) -> 4000665.9 | R11: =IF(R10+Bin_Size>Bin_Stop,"",R10+Bin_Size) -> 4250000 | S11: 40 | T11: =IF(ISBLANK(S11),"",SUM($S$6:S11)/Total_Trials) -> 0.508
R12: =IF(R11+Bin_Size>Bin_Stop,"",R11+Bin_Size) -> 4900000 | S12: 55 | T12: =IF(ISBLANK(S12),"",SUM($S$6:S12)/Total_Trials) -> 0.728
E13: Bins Number | F13: =ROUNDUP(Range_of_Profits/F11,0) -> 8 | H13: Risk Profile of Profit | R13: =IF(R12+Bin_Size>Bin_Stop,"",R12+Bin_Size) -> 5550000 | S13: 52 | T13: =IF(ISBLANK(S13),"",SUM($S$6:S13)/Total_Trials) -> 0.936
R14: =IF(R13+Bin_Size>Bin_Stop,"",R13+Bin_Size) -> 6200000 | S14: 16 | T14: =IF(ISBLANK(S14),"",SUM($S$6:S14)/Total_Trials) -> 1
D15: Probability | E15: Cutoffs | F15: Share % | H15: Minimum Profit | I15: =MIN(Table14[Profit]) -> 1333610 | S15: 0 | T15: =IF(ISBLANK(S15),"",SUM($S$6:S15)/Total_Trials) -> 1
D16: 0.05 | E16: 0 | F16: 0.2 | H16: Maximum Profit | I16: =MAX(Table14[Profit]) -> 6076583.6 | S16: #N/A | T16: =IF(ISBLANK(S16),"",SUM($S$6:S16)/Total_Trials) -> #N/A
D17: 0.1 | E17: =E16+D16 -> 0.05 | F17: 0.3 | H17: Range of Profits | I17: =I16-I15 -> 4742973.5 | S17: #N/A | T17: =IF(ISBLANK(S17),"",SUM($S$6:S17)/Total_Trials) -> #N/A
D18: 0.15 | E18: =E17+D17 -> 0.15 | F18: 0.4 | H18: Trials below Mean | I18: =COUNTIF(Table14[Profit],"<"&H11) -> 117 | S18: #N/A | T18: =IF(ISBLANK(S18),"",SUM($S$6:S18)/Total_Trials) -> #N/A
D19: 0.2 | E19: =E18+D18 -> 0.3 | F19: 0.5 | H19: Total Trials | I19: =COUNT(Table14[Trial]) -> 250 | S19: #N/A | T19: =IF(ISBLANK(S19),"",SUM($S$6:S19)/Total_Trials) -> #N/A
D20: 0.25 | E20: =E19+D19 -> 0.5 | F20: 0.6 | H20: Chance of below average profit | S20: #N/A | T20: =IF(ISBLANK(S20),"",SUM($S$6:S20)/Total_Trials) -> #N/A
D21: 0.25 | E21: =E20+D20 -> 0.75 | F21: 0.7 | I21: =Trials_below_Mean/Total_Trials -> 0.468 | S21: #N/A | T21: =IF(ISBLANK(S21),"",SUM($S$6:S21)/Total_Trials) -> #N/A
H22: Chance of maximum profit | S22: #N/A | T22: =IF(ISBLANK(S22),"",SUM($S$6:S22)/Total_Trials) -> #N/A
D23: Notes: (1) Grey cells should not be changed once | I23: =COUNTIF(Table14[Profit],Maximum_Profit)/Total_Trials -> 0.004 | S23: #N/A | T23: =IF(ISBLANK(S23),"",SUM($S$6:S23)/Total_Trials) -> #N/A
D24: you have learnt the formulas that go into them. | S24: #N/A | T24: =IF(ISBLANK(S24),"",SUM($S$6:S24)/Total_Trials) -> #N/A
D25: (2) Use "Select Data" in chart right-click menu to | S25: #N/A | T25: =IF(ISBLANK(S25),"",SUM($S$6:S25)/Total_Trials) -> #N/A
D26: adjust to only non-error part of risk profile data | S26: #N/A | T26: =IF(ISBLANK(S26),"",SUM($S$6:S26)/Total_Trials) -> #N/A
A27: Simulated Trials of Demand and Profits | S27: #N/A | T27: =IF(ISBLANK(S27),"",SUM($S$6:S27)/Total_Trials) -> #N/A
A28: Trial | B28: Random # for LT Demand | C28: Lead Time Demand | D28: Random # for Share | E28: Share % (based on Random #) | F28: Share of Lead Time Demand (Units) | G28: Revenue | H28: Costs | I28: Profit | S28: #N/A | T28: =IF(ISBLANK(S28),"",SUM($S$6:S28)/Total_Trials) -> #N/A
A29: 1 | B29: =RAND() -> 0.22543339 | C29: =_xlfn.NORM.INV(Table14[[#This Row],[Random '# for LT Demand]],Expected_LT_Demand,$F$8)*1000 -> 1809612.7 | D29: =RAND() -> 0.52809928 | E29: =VLOOKUP(Table14[[#This Row],[Random '# for Share ]],$E$16:$F$21,2,TRUE) -> 0.6 | F29: =Table14[[#This Row],[Lead Time Demand]]*Table14[[#This Row],[Share % (based on Random '#)]] -> 1085767.6 | G29: =Table14[[#This Row],[Share of Lead Time Demand (Units)]]*Unit_price -> 8686141 | H29: =Table14[[#This Row],[Share of Lead Time Demand (Units)]]*Unit_cost -> 4343070.5 | I29: =Table14[[#This Row],[Revenue]]-Table14[[#This Row],[Costs]] -> 4343070.5 | T29: =IF(ISBLANK(S29),"",SUM($S$6:S29)/Total_Trials)
A30: 2 | B30: =RAND() -> 0.7559129 | C30: =_xlfn.NORM.INV(Table14[[#This Row],[Random '# for LT Demand]],Expected_LT_Demand,$F$8)*1000 -> 1985560.9 | D30: =RAND() -> 0.26609399 | E30: =VLOOKUP(Table14[[#This Row],[Random '# for Share ]],$E$16:$F$21,2,TRUE) -> 0.4 | F30: =Table14[[#This Row],[Lead Time Demand]]*Table14[[#This Row],[Share % (based on Random '#)]] -> 794224.36 | G30: =Table14[[#This Row],[Share of Lead Time Demand (Units)]]*Unit_price -> 6353794.8 | H30: =Table14[[#This Row],[Share of Lead Time Demand (Units)]]*Unit_cost -> 3176897.4 | I30: =Table14[[#This Row],[Revenue]]-Table14[[#This Row],[Costs]] -> 3176897.4 | T30: =IF(ISBLANK(S30),"",SUM($S$6:S30)/Total_Trials)
A31: 3 | B31: =RAND() -> 0.62466239 | C31: =_xlfn.NORM.INV(Table14[[#This Row],[Random '# for LT Demand]],Expected_LT_Demand,$F$8)*1000 -> 1939911.9 | D31: =RAND() -> 0.23041352 | E31: =VLOOKUP(Table14[[#This Row],[Random '# for Share ]],$E$16:$F$21,2,TRUE) -> 0.4 | F31: =Table14[[#This Row],[Lead Time Demand]]*Table14[[#This Row],[Share % (based on Random '#)]] -> 775964.74 | G31: =Table14[[#This Row],[Share of Lead Time Demand (Units)]]*Unit_price -> 6207717.9 | H31: =Table14[[#This Row],[Share of Lead Time Demand (Units)]]*Unit_cost -> 3103859 | I31: =Table14[[#This Row],[Revenue]]-Table14[[#This Row],[Costs]] -> 3103859 | T31: =IF(ISBLANK(S31),"",SUM($S$6:S31)/Total_Trials)
A32: 4 | B32: =RAND() -> 0.21235343 | C32: =_xlfn.NORM.INV(Table14[[#This Row],[Random '# for LT Demand]],Expected_LT_Demand,$F$8)*1000 -> 1804225.4 | D32: =RAND() -> 0.16734461 | E32: =VLOOKUP(Table14[[#This Row],[Random '# for Share ]],$E$16:$F$21,2,TRUE) -> 0.4 | F32: =Table14[[#This Row],[Lead Time Demand]]*Table14[[#This Row],[Share % (based on Random '#)]] -> 721690.14 | G32: =Table14[[#This Row],[Share of Lead Time Demand (Units)]]*Unit_price -> 5773521.2 | H32: =Table14[[#This Row],[Share of Lead Time Demand (Units)]]*Unit_cost -> 2886760.6 | I32: =Table14[[#This Row],[Revenue]]-Table14[[#This Row],[Costs]] -> 2886760.6
A33: 5 | B33: =RAND() -> 0.68657808 | C33: =_xlfn.NORM.INV(Table14[[#This Row],[Random '# for LT Demand]],Expected_LT_Demand,$F$8)*1000 -> 1960388.9 | D33: =RAND() -> 0.85043189 | E33: =VLOOKUP(Table14[[#This Row],[Random '# for Share ]],$E$16:$F$21,2,TRUE) -> 0.7 | F33: =Table14[[#This Row],[Lead Time Demand]]*Table14[[#This Row],[Share % (based on Random '#)]] -> 1372272.2 | G33: =Table14[[#This Row],[Share of Lead Time Demand (Units)]]*Unit_price -> 10978178 | H33: =Table14[[#This Row],[Share of Lead Time Demand (Units)]]*Unit_cost -> 5489088.8 | I33: =Table14[[#This Row],[Revenue]]-Table14[[#This Row],[Costs]] -> 5489088.8
A34: 6 | B34: =RAND() -> 0.77510256 | C34: =_xlfn.NORM.INV(Table14[[#This Row],[Random '# for LT Demand]],Expected_LT_Demand,$F$8)*1000 -> 1993164.6 | D34: =RAND() -> 0.68333413 | E34: =VLOOKUP(Table14[[#This Row],[Random '# for Share ]],$E$16:$F$21,2,TRUE) -> 0.6 | F34: =Table14[[#This Row],[Lead Time Demand]]*Table14[[#This Row],[Share % (based on Random '#)]] -> 1195898.8 | G34: =Table14[[#This Row],[Share of Lead Time Demand (Units)]]*Unit_price -> 9567190.2 | H34: =Table14[[#This Row],[Share of Lead Time Demand (Units)]]*Unit_cost -> 4783595.1 | I34: =Table14[[#This Row],[Revenue]]-Table14[[#This Row],[Costs]] -> 4783595.1
A35: 7 | B35: =RAND() -> 0.57517814 | C35: =_xlfn.NORM.INV(Table14[[#This Row],[Random '# for LT Demand]],Expected_LT_Demand,$F$8)*1000 -> 1924328.3 | D35: =RAND() -> 0.082828249 | E35: =VLOOKUP(Table14[[#This Row],[Random '# for Share ]],$E$16:$F$21,2,TRUE) -> 0.3 | F35: =Table14[[#This Row],[Lead Time Demand]]*Table14[[#This Row],[Share % (based on Random '#)]] -> 577298.48 | G35: =Table14[[#This Row],[Share of Lead Time Demand (Units)]]*Unit_price -> 4618387.8 | H35: =Table14[[#This Row],[Share of Lead Time Demand (Units)]]*Unit_cost -> 2309193.9 | I35: =Table14[[#This Row],[Revenue]]-Table14[[#This Row],[Costs]] -> 2309193.9
A36: 8 | B36: =RAND() -> 0.7894127 | C36: =_xlfn.NORM.INV(Table14[[#This Row],[Random '# for LT Demand]],Expected_LT_Demand,$F$8)*1000 -> 1999076.8 | D36: =RAND() -> 0.97550727 | E36: =VLOOKUP(Table14[[#This Row],[Random '# for Share ]],$E$16:$F$21,2,TRUE) -> 0.7 | F36: =Table14[[#This Row],[Lead Time Demand]]*Table14[[#This Row],[Share % (based on Random '#)]] -> 1399353.8 | G36: =Table14[[#This Row],[Share of Lead Time Demand (Units)]]*Unit_price -> 11194830 | H36: =Table14[[#This Row],[Share of Lead Time Demand (Units)]]*Unit_cost -> 5597415.1 | I36: =Table14[[#This Row],[Revenue]]-Table14[[#This Row],[Costs]] -> 5597415.1
A37: 9 | B37: =RAND() -> 0.86989883 | C37: =_xlfn.NORM.INV(Table14[[#This Row],[Random '# for LT Demand]],Expected_LT_Demand,$F$8)*1000 -> 2038168 | D37: =RAND() -> 0.98716457 | E37: =VLOOKUP(Table14[[#This Row],[Random '# for Share ]],$E$16:$F$21,2,TRUE) -> 0.7 | F37: =Table14[[#This Row],[Lead Time Demand]]*Table14[[#This Row],[Share % (based on Random '#)]] -> 1426717.6 | G37: =Table14[[#This Row],[Share of Lead Time Demand (Units)]]*Unit_price -> 11413741 | H37: =Table14[[#This Row],[Share of Lead Time Demand (Units)]]*Unit_cost -> 5706870.4 | I37: =Table14[[#This Row],[Revenue]]-Table14[[#This Row],[Costs]] -> 5706870.4
A38: 10 | B38: =RAND() -> 0.89712617 | C38: =_xlfn.NORM.INV(Table14[[#This Row],[Random '# for LT Demand]],Expected_LT_Demand,$F$8)*1000 -> 2055120.1 | D38: =RAND() -> 0.87015359 | E38: =VLOOKUP(Table14[[#This Row],[Random '# for Share ]],$E$16:$F$21,2,TRUE) -> 0.7 | F38: =Table14[[#This Row],[Lead Time Demand]]*Table14[[#This Row],[Share % (based on Random '#)]] -> 1438584.1 | G38: =Table14[[#This Row],[Share of Lead Time Demand (Units)]]*Unit_price -> 11508672 | H38: =Table14[[#This Row],[Share of Lead Time Demand (Units)]]*Unit_cost -> 5754336.2 | I38: =Table14[[#This Row],[Revenue]]-Table14[[#This Row],[Costs]] -> 5754336.2
A39: 11 | B39: =RAND() -> 0.31846537 | C39: =_xlfn.NORM.INV(Table14[[#This Row],[Random '# for LT Demand]],Expected_LT_Demand,$F$8)*1000 -> 1843895.2 | D39: =RAND() -> 0.28086771 | E39: =VLOOKUP(Table14[[#This Row],[Random '# for Share ]],$E$16:$F$21,2,TRUE) -> 0.4 | F39: =Table14[[#This Row],[Lead Time Demand]]*Table14[[#This Row],[Share % (based on Random '#)]] -> 737558.09 | G39: =Table14[[#This Row],[Share of Lead Time Demand (Units)]]*Unit_price -> 5900464.7 | H39: =Table14[[#This Row],[Share of Lead Time Demand (Units)]]*Unit_cost -> 2950232.4 | I39: =Table14[[#This Row],[Revenue]]-Table14[[#This Row],[Costs]] -> 2950232.4
A40: 12 | B40: =RAND() -> 0.9229844 | C40: =_xlfn.NORM.INV(Table14[[#This Row],[Random '# for LT Demand]],Expected_LT_Demand,$F$8)*1000 -> 2074583.9 | D40: =RAND() -> 0.8319977 | E40: =VLOOKUP(Table14[[#This Row],[Random '# for Share ]],$E$16:$F$21,2,TRUE) -> 0.7 | F40: =Table14[[#This Row],[Lead Time Demand]]*Table14[[#This Row],[Share % (based on Random '#)]] -> 1452208.7 | G40: =Table14[[#This Row],[Share of Lead Time Demand (Units)]]*Unit_price -> 11617670 | H40: =Table14[[#This Row],[Share of Lead Time Demand (Units)]]*Unit_cost -> 5808834.8 | I40: =Table14[[#This Row],[Revenue]]-Table14[[#This Row],[Costs]] -> 5808834.8
...
